2020-11-07 03:57:33,233 INFO root Loading cache from /media/compute/homes/aharter/.cache/phyre/offline_simulation/100000/ball
2020-11-07 03:57:41,298 INFO __main__ VS-bigbase2 ball_within_template 0 -1 || loading models...
2020-11-07 03:57:41,302 ERROR __main__ Exception occured:
Traceback (most recent call last):
  File "solver.py", line 231, in <module>
    solver.load_models(setup=eval_setup, fold=fold_id, no_second_stage=no_scnd_stage, load_from=load_from)
  File "/media/compute/homes/aharter/isy2020/phyre/flownet.py", line 2763, in load_models
    self.models[model].load_state_dict(T.load(load_path+f'/{model}.pt', map_location=T.device(device)))
  File "/media/compute/homes/aharter/miniconda3/envs/phyre/lib/python3.6/site-packages/torch/serialization.py", line 571, in load
    with _open_file_like(f, 'rb') as opened_file:
  File "/media/compute/homes/aharter/miniconda3/envs/phyre/lib/python3.6/site-packages/torch/serialization.py", line 229, in _open_file_like
    return _open_file(name_or_buffer, mode)
  File "/media/compute/homes/aharter/miniconda3/envs/phyre/lib/python3.6/site-packages/torch/serialization.py", line 210, in __init__
    super(_open_file, self).__init__(open(name, mode))
FileNotFoundError: [Errno 2] No such file or directory: 'saves/flownet/VS-bigbase2_within_0_-1/tar_net.pt'
2020-11-07 04:04:23,297 INFO root Loading cache from /media/compute/homes/aharter/.cache/phyre/offline_simulation/100000/ball
2020-11-07 04:04:30,820 INFO __main__ VS-bigbase2 ball_within_template 0 -1 || loading models...
2020-11-07 04:04:30,823 ERROR __main__ Exception occured:
Traceback (most recent call last):
  File "solver.py", line 231, in <module>
    solver.load_models(setup=eval_setup, fold=fold_id, no_second_stage=no_scnd_stage, load_from=load_from)
  File "/media/compute/homes/aharter/isy2020/phyre/flownet.py", line 2763, in load_models
    self.models[model].load_state_dict(T.load(load_path+f'/{model}.pt', map_location=T.device(device)))
  File "/media/compute/homes/aharter/miniconda3/envs/phyre/lib/python3.6/site-packages/torch/serialization.py", line 571, in load
    with _open_file_like(f, 'rb') as opened_file:
  File "/media/compute/homes/aharter/miniconda3/envs/phyre/lib/python3.6/site-packages/torch/serialization.py", line 229, in _open_file_like
    return _open_file(name_or_buffer, mode)
  File "/media/compute/homes/aharter/miniconda3/envs/phyre/lib/python3.6/site-packages/torch/serialization.py", line 210, in __init__
    super(_open_file, self).__init__(open(name, mode))
FileNotFoundError: [Errno 2] No such file or directory: 'saves/flownet/VS-bigbase2_within_0_-1/tar_net.pt'
2020-11-07 04:11:06,951 INFO root Loading cache from /media/compute/homes/aharter/.cache/phyre/offline_simulation/100000/ball
2020-11-07 04:11:14,710 INFO __main__ VS-bigbase2 ball_within_template 0 -1 || loading models...
2020-11-07 04:11:14,713 ERROR __main__ Exception occured:
Traceback (most recent call last):
  File "solver.py", line 231, in <module>
    solver.load_models(setup=eval_setup, fold=fold_id, no_second_stage=no_scnd_stage, load_from=load_from)
  File "/media/compute/homes/aharter/isy2020/phyre/flownet.py", line 2763, in load_models
    self.models[model].load_state_dict(T.load(load_path+f'/{model}.pt', map_location=T.device(device)))
  File "/media/compute/homes/aharter/miniconda3/envs/phyre/lib/python3.6/site-packages/torch/serialization.py", line 571, in load
    with _open_file_like(f, 'rb') as opened_file:
  File "/media/compute/homes/aharter/miniconda3/envs/phyre/lib/python3.6/site-packages/torch/serialization.py", line 229, in _open_file_like
    return _open_file(name_or_buffer, mode)
  File "/media/compute/homes/aharter/miniconda3/envs/phyre/lib/python3.6/site-packages/torch/serialization.py", line 210, in __init__
    super(_open_file, self).__init__(open(name, mode))
FileNotFoundError: [Errno 2] No such file or directory: 'saves/flownet/VS-bigbase2_within_0_-1/tar_net.pt'
2020-11-07 04:17:57,645 INFO root Loading cache from /media/compute/homes/aharter/.cache/phyre/offline_simulation/100000/ball
2020-11-07 04:18:05,668 INFO __main__ VS-bigbase2 ball_within_template 0 -1 || loading models...
2020-11-07 04:18:05,672 ERROR __main__ Exception occured:
Traceback (most recent call last):
  File "solver.py", line 231, in <module>
    solver.load_models(setup=eval_setup, fold=fold_id, no_second_stage=no_scnd_stage, load_from=load_from)
  File "/media/compute/homes/aharter/isy2020/phyre/flownet.py", line 2763, in load_models
    self.models[model].load_state_dict(T.load(load_path+f'/{model}.pt', map_location=T.device(device)))
  File "/media/compute/homes/aharter/miniconda3/envs/phyre/lib/python3.6/site-packages/torch/serialization.py", line 571, in load
    with _open_file_like(f, 'rb') as opened_file:
  File "/media/compute/homes/aharter/miniconda3/envs/phyre/lib/python3.6/site-packages/torch/serialization.py", line 229, in _open_file_like
    return _open_file(name_or_buffer, mode)
  File "/media/compute/homes/aharter/miniconda3/envs/phyre/lib/python3.6/site-packages/torch/serialization.py", line 210, in __init__
    super(_open_file, self).__init__(open(name, mode))
FileNotFoundError: [Errno 2] No such file or directory: 'saves/flownet/VS-bigbase2_within_0_-1/tar_net.pt'
2020-11-07 04:24:49,904 INFO root Loading cache from /media/compute/homes/aharter/.cache/phyre/offline_simulation/100000/ball
2020-11-07 04:24:57,913 INFO __main__ VS-bigbase2 ball_within_template 0 -1 || loading models...
2020-11-07 04:24:57,915 ERROR __main__ Exception occured:
Traceback (most recent call last):
  File "solver.py", line 231, in <module>
    solver.load_models(setup=eval_setup, fold=fold_id, no_second_stage=no_scnd_stage, load_from=load_from)
  File "/media/compute/homes/aharter/isy2020/phyre/flownet.py", line 2763, in load_models
    self.models[model].load_state_dict(T.load(load_path+f'/{model}.pt', map_location=T.device(device)))
  File "/media/compute/homes/aharter/miniconda3/envs/phyre/lib/python3.6/site-packages/torch/serialization.py", line 571, in load
    with _open_file_like(f, 'rb') as opened_file:
  File "/media/compute/homes/aharter/miniconda3/envs/phyre/lib/python3.6/site-packages/torch/serialization.py", line 229, in _open_file_like
    return _open_file(name_or_buffer, mode)
  File "/media/compute/homes/aharter/miniconda3/envs/phyre/lib/python3.6/site-packages/torch/serialization.py", line 210, in __init__
    super(_open_file, self).__init__(open(name, mode))
FileNotFoundError: [Errno 2] No such file or directory: 'saves/flownet/VS-bigbase2_within_0_-1/tar_net.pt'
2020-11-07 04:31:40,340 INFO root Loading cache from /media/compute/homes/aharter/.cache/phyre/offline_simulation/100000/ball
2020-11-07 04:31:48,312 INFO __main__ VS-bigbase2 ball_within_template 0 -1 || loading models...
2020-11-07 04:31:48,316 ERROR __main__ Exception occured:
Traceback (most recent call last):
  File "solver.py", line 231, in <module>
    solver.load_models(setup=eval_setup, fold=fold_id, no_second_stage=no_scnd_stage, load_from=load_from)
  File "/media/compute/homes/aharter/isy2020/phyre/flownet.py", line 2763, in load_models
    self.models[model].load_state_dict(T.load(load_path+f'/{model}.pt', map_location=T.device(device)))
  File "/media/compute/homes/aharter/miniconda3/envs/phyre/lib/python3.6/site-packages/torch/serialization.py", line 571, in load
    with _open_file_like(f, 'rb') as opened_file:
  File "/media/compute/homes/aharter/miniconda3/envs/phyre/lib/python3.6/site-packages/torch/serialization.py", line 229, in _open_file_like
    return _open_file(name_or_buffer, mode)
  File "/media/compute/homes/aharter/miniconda3/envs/phyre/lib/python3.6/site-packages/torch/serialization.py", line 210, in __init__
    super(_open_file, self).__init__(open(name, mode))
FileNotFoundError: [Errno 2] No such file or directory: 'saves/flownet/VS-bigbase2_within_0_-1/tar_net.pt'
2020-11-07 04:38:30,150 INFO root Loading cache from /media/compute/homes/aharter/.cache/phyre/offline_simulation/100000/ball
2020-11-07 04:38:38,122 INFO __main__ VS-bigbase2 ball_within_template 0 -1 || loading models...
2020-11-07 04:38:38,126 ERROR __main__ Exception occured:
Traceback (most recent call last):
  File "solver.py", line 231, in <module>
    solver.load_models(setup=eval_setup, fold=fold_id, no_second_stage=no_scnd_stage, load_from=load_from)
  File "/media/compute/homes/aharter/isy2020/phyre/flownet.py", line 2763, in load_models
    self.models[model].load_state_dict(T.load(load_path+f'/{model}.pt', map_location=T.device(device)))
  File "/media/compute/homes/aharter/miniconda3/envs/phyre/lib/python3.6/site-packages/torch/serialization.py", line 571, in load
    with _open_file_like(f, 'rb') as opened_file:
  File "/media/compute/homes/aharter/miniconda3/envs/phyre/lib/python3.6/site-packages/torch/serialization.py", line 229, in _open_file_like
    return _open_file(name_or_buffer, mode)
  File "/media/compute/homes/aharter/miniconda3/envs/phyre/lib/python3.6/site-packages/torch/serialization.py", line 210, in __init__
    super(_open_file, self).__init__(open(name, mode))
FileNotFoundError: [Errno 2] No such file or directory: 'saves/flownet/VS-bigbase2_within_0_-1/tar_net.pt'
2020-11-07 04:45:22,718 INFO root Loading cache from /media/compute/homes/aharter/.cache/phyre/offline_simulation/100000/ball
2020-11-07 04:45:30,669 INFO __main__ VS-bigbase2 ball_within_template 0 -1 || loading models...
2020-11-07 04:45:30,674 ERROR __main__ Exception occured:
Traceback (most recent call last):
  File "solver.py", line 231, in <module>
    solver.load_models(setup=eval_setup, fold=fold_id, no_second_stage=no_scnd_stage, load_from=load_from)
  File "/media/compute/homes/aharter/isy2020/phyre/flownet.py", line 2763, in load_models
    self.models[model].load_state_dict(T.load(load_path+f'/{model}.pt', map_location=T.device(device)))
  File "/media/compute/homes/aharter/miniconda3/envs/phyre/lib/python3.6/site-packages/torch/serialization.py", line 571, in load
    with _open_file_like(f, 'rb') as opened_file:
  File "/media/compute/homes/aharter/miniconda3/envs/phyre/lib/python3.6/site-packages/torch/serialization.py", line 229, in _open_file_like
    return _open_file(name_or_buffer, mode)
  File "/media/compute/homes/aharter/miniconda3/envs/phyre/lib/python3.6/site-packages/torch/serialization.py", line 210, in __init__
    super(_open_file, self).__init__(open(name, mode))
FileNotFoundError: [Errno 2] No such file or directory: 'saves/flownet/VS-bigbase2_within_0_-1/tar_net.pt'
2020-11-07 04:52:12,344 INFO root Loading cache from /media/compute/homes/aharter/.cache/phyre/offline_simulation/100000/ball
2020-11-07 04:52:20,326 INFO __main__ VS-bigbase2 ball_within_template 0 -1 || loading models...
2020-11-07 04:52:20,328 ERROR __main__ Exception occured:
Traceback (most recent call last):
  File "solver.py", line 231, in <module>
    solver.load_models(setup=eval_setup, fold=fold_id, no_second_stage=no_scnd_stage, load_from=load_from)
  File "/media/compute/homes/aharter/isy2020/phyre/flownet.py", line 2763, in load_models
    self.models[model].load_state_dict(T.load(load_path+f'/{model}.pt', map_location=T.device(device)))
  File "/media/compute/homes/aharter/miniconda3/envs/phyre/lib/python3.6/site-packages/torch/serialization.py", line 571, in load
    with _open_file_like(f, 'rb') as opened_file:
  File "/media/compute/homes/aharter/miniconda3/envs/phyre/lib/python3.6/site-packages/torch/serialization.py", line 229, in _open_file_like
    return _open_file(name_or_buffer, mode)
  File "/media/compute/homes/aharter/miniconda3/envs/phyre/lib/python3.6/site-packages/torch/serialization.py", line 210, in __init__
    super(_open_file, self).__init__(open(name, mode))
FileNotFoundError: [Errno 2] No such file or directory: 'saves/flownet/VS-bigbase2_within_0_-1/tar_net.pt'
2020-11-07 04:59:02,604 INFO root Loading cache from /media/compute/homes/aharter/.cache/phyre/offline_simulation/100000/ball
2020-11-07 04:59:10,876 INFO __main__ VS-bigbase2 ball_within_template 0 -1 || loading models...
2020-11-07 04:59:10,878 ERROR __main__ Exception occured:
Traceback (most recent call last):
  File "solver.py", line 231, in <module>
    solver.load_models(setup=eval_setup, fold=fold_id, no_second_stage=no_scnd_stage, load_from=load_from)
  File "/media/compute/homes/aharter/isy2020/phyre/flownet.py", line 2763, in load_models
    self.models[model].load_state_dict(T.load(load_path+f'/{model}.pt', map_location=T.device(device)))
  File "/media/compute/homes/aharter/miniconda3/envs/phyre/lib/python3.6/site-packages/torch/serialization.py", line 571, in load
    with _open_file_like(f, 'rb') as opened_file:
  File "/media/compute/homes/aharter/miniconda3/envs/phyre/lib/python3.6/site-packages/torch/serialization.py", line 229, in _open_file_like
    return _open_file(name_or_buffer, mode)
  File "/media/compute/homes/aharter/miniconda3/envs/phyre/lib/python3.6/site-packages/torch/serialization.py", line 210, in __init__
    super(_open_file, self).__init__(open(name, mode))
FileNotFoundError: [Errno 2] No such file or directory: 'saves/flownet/VS-bigbase2_within_0_-1/tar_net.pt'
