2020-11-07 03:50:57,373 INFO root Loading cache from /media/compute/homes/aharter/.cache/phyre/offline_simulation/100000/ball
2020-11-07 03:51:05,522 INFO __main__ VS-bigbase2 ball_within_template 0 -1 || loading models...
2020-11-07 03:51:05,529 ERROR __main__ Exception occured:
Traceback (most recent call last):
  File "solver.py", line 231, in <module>
    solver.load_models(setup=eval_setup, fold=fold_id, no_second_stage=no_scnd_stage, load_from=load_from)
  File "/media/compute/homes/aharter/isy2020/phyre/flownet.py", line 2763, in load_models
    self.models[model].load_state_dict(T.load(load_path+f'/{model}.pt', map_location=T.device(device)))
  File "/media/compute/homes/aharter/miniconda3/envs/phyre/lib/python3.6/site-packages/torch/serialization.py", line 571, in load
    with _open_file_like(f, 'rb') as opened_file:
  File "/media/compute/homes/aharter/miniconda3/envs/phyre/lib/python3.6/site-packages/torch/serialization.py", line 229, in _open_file_like
    return _open_file(name_or_buffer, mode)
  File "/media/compute/homes/aharter/miniconda3/envs/phyre/lib/python3.6/site-packages/torch/serialization.py", line 210, in __init__
    super(_open_file, self).__init__(open(name, mode))
FileNotFoundError: [Errno 2] No such file or directory: 'saves/flownet/VS-bigbase2_within_0_-1/tar_net.pt'
2020-11-07 03:57:47,530 INFO root Loading cache from /media/compute/homes/aharter/.cache/phyre/offline_simulation/100000/ball
2020-11-07 03:57:55,573 INFO __main__ VS-bigbase2 ball_within_template 0 -1 || loading models...
2020-11-07 03:57:55,576 ERROR __main__ Exception occured:
Traceback (most recent call last):
  File "solver.py", line 231, in <module>
    solver.load_models(setup=eval_setup, fold=fold_id, no_second_stage=no_scnd_stage, load_from=load_from)
  File "/media/compute/homes/aharter/isy2020/phyre/flownet.py", line 2763, in load_models
    self.models[model].load_state_dict(T.load(load_path+f'/{model}.pt', map_location=T.device(device)))
  File "/media/compute/homes/aharter/miniconda3/envs/phyre/lib/python3.6/site-packages/torch/serialization.py", line 571, in load
    with _open_file_like(f, 'rb') as opened_file:
  File "/media/compute/homes/aharter/miniconda3/envs/phyre/lib/python3.6/site-packages/torch/serialization.py", line 229, in _open_file_like
    return _open_file(name_or_buffer, mode)
  File "/media/compute/homes/aharter/miniconda3/envs/phyre/lib/python3.6/site-packages/torch/serialization.py", line 210, in __init__
    super(_open_file, self).__init__(open(name, mode))
FileNotFoundError: [Errno 2] No such file or directory: 'saves/flownet/VS-bigbase2_within_0_-1/tar_net.pt'
2020-11-07 04:04:36,548 INFO root Loading cache from /media/compute/homes/aharter/.cache/phyre/offline_simulation/100000/ball
2020-11-07 04:04:42,379 INFO __main__ VS-bigbase2 ball_within_template 0 -1 || loading models...
2020-11-07 04:04:42,382 ERROR __main__ Exception occured:
Traceback (most recent call last):
  File "solver.py", line 231, in <module>
    solver.load_models(setup=eval_setup, fold=fold_id, no_second_stage=no_scnd_stage, load_from=load_from)
  File "/media/compute/homes/aharter/isy2020/phyre/flownet.py", line 2763, in load_models
    self.models[model].load_state_dict(T.load(load_path+f'/{model}.pt', map_location=T.device(device)))
  File "/media/compute/homes/aharter/miniconda3/envs/phyre/lib/python3.6/site-packages/torch/serialization.py", line 571, in load
    with _open_file_like(f, 'rb') as opened_file:
  File "/media/compute/homes/aharter/miniconda3/envs/phyre/lib/python3.6/site-packages/torch/serialization.py", line 229, in _open_file_like
    return _open_file(name_or_buffer, mode)
  File "/media/compute/homes/aharter/miniconda3/envs/phyre/lib/python3.6/site-packages/torch/serialization.py", line 210, in __init__
    super(_open_file, self).__init__(open(name, mode))
FileNotFoundError: [Errno 2] No such file or directory: 'saves/flownet/VS-bigbase2_within_0_-1/tar_net.pt'
2020-11-07 04:11:20,934 INFO root Loading cache from /media/compute/homes/aharter/.cache/phyre/offline_simulation/100000/ball
2020-11-07 04:11:29,201 INFO __main__ VS-bigbase2 ball_within_template 0 -1 || loading models...
2020-11-07 04:11:29,208 ERROR __main__ Exception occured:
Traceback (most recent call last):
  File "solver.py", line 231, in <module>
    solver.load_models(setup=eval_setup, fold=fold_id, no_second_stage=no_scnd_stage, load_from=load_from)
  File "/media/compute/homes/aharter/isy2020/phyre/flownet.py", line 2763, in load_models
    self.models[model].load_state_dict(T.load(load_path+f'/{model}.pt', map_location=T.device(device)))
  File "/media/compute/homes/aharter/miniconda3/envs/phyre/lib/python3.6/site-packages/torch/serialization.py", line 571, in load
    with _open_file_like(f, 'rb') as opened_file:
  File "/media/compute/homes/aharter/miniconda3/envs/phyre/lib/python3.6/site-packages/torch/serialization.py", line 229, in _open_file_like
    return _open_file(name_or_buffer, mode)
  File "/media/compute/homes/aharter/miniconda3/envs/phyre/lib/python3.6/site-packages/torch/serialization.py", line 210, in __init__
    super(_open_file, self).__init__(open(name, mode))
FileNotFoundError: [Errno 2] No such file or directory: 'saves/flownet/VS-bigbase2_within_0_-1/tar_net.pt'
2020-11-07 04:18:11,867 INFO root Loading cache from /media/compute/homes/aharter/.cache/phyre/offline_simulation/100000/ball
2020-11-07 04:18:19,786 INFO __main__ VS-bigbase2 ball_within_template 0 -1 || loading models...
2020-11-07 04:18:19,789 ERROR __main__ Exception occured:
Traceback (most recent call last):
  File "solver.py", line 231, in <module>
    solver.load_models(setup=eval_setup, fold=fold_id, no_second_stage=no_scnd_stage, load_from=load_from)
  File "/media/compute/homes/aharter/isy2020/phyre/flownet.py", line 2763, in load_models
    self.models[model].load_state_dict(T.load(load_path+f'/{model}.pt', map_location=T.device(device)))
  File "/media/compute/homes/aharter/miniconda3/envs/phyre/lib/python3.6/site-packages/torch/serialization.py", line 571, in load
    with _open_file_like(f, 'rb') as opened_file:
  File "/media/compute/homes/aharter/miniconda3/envs/phyre/lib/python3.6/site-packages/torch/serialization.py", line 229, in _open_file_like
    return _open_file(name_or_buffer, mode)
  File "/media/compute/homes/aharter/miniconda3/envs/phyre/lib/python3.6/site-packages/torch/serialization.py", line 210, in __init__
    super(_open_file, self).__init__(open(name, mode))
FileNotFoundError: [Errno 2] No such file or directory: 'saves/flownet/VS-bigbase2_within_0_-1/tar_net.pt'
2020-11-07 04:25:04,067 INFO root Loading cache from /media/compute/homes/aharter/.cache/phyre/offline_simulation/100000/ball
2020-11-07 04:25:11,983 INFO __main__ VS-bigbase2 ball_within_template 0 -1 || loading models...
2020-11-07 04:25:11,986 ERROR __main__ Exception occured:
Traceback (most recent call last):
  File "solver.py", line 231, in <module>
    solver.load_models(setup=eval_setup, fold=fold_id, no_second_stage=no_scnd_stage, load_from=load_from)
  File "/media/compute/homes/aharter/isy2020/phyre/flownet.py", line 2763, in load_models
    self.models[model].load_state_dict(T.load(load_path+f'/{model}.pt', map_location=T.device(device)))
  File "/media/compute/homes/aharter/miniconda3/envs/phyre/lib/python3.6/site-packages/torch/serialization.py", line 571, in load
    with _open_file_like(f, 'rb') as opened_file:
  File "/media/compute/homes/aharter/miniconda3/envs/phyre/lib/python3.6/site-packages/torch/serialization.py", line 229, in _open_file_like
    return _open_file(name_or_buffer, mode)
  File "/media/compute/homes/aharter/miniconda3/envs/phyre/lib/python3.6/site-packages/torch/serialization.py", line 210, in __init__
    super(_open_file, self).__init__(open(name, mode))
FileNotFoundError: [Errno 2] No such file or directory: 'saves/flownet/VS-bigbase2_within_0_-1/tar_net.pt'
2020-11-07 04:31:54,470 INFO root Loading cache from /media/compute/homes/aharter/.cache/phyre/offline_simulation/100000/ball
2020-11-07 04:32:02,465 INFO __main__ VS-bigbase2 ball_within_template 0 -1 || loading models...
2020-11-07 04:32:02,470 ERROR __main__ Exception occured:
Traceback (most recent call last):
  File "solver.py", line 231, in <module>
    solver.load_models(setup=eval_setup, fold=fold_id, no_second_stage=no_scnd_stage, load_from=load_from)
  File "/media/compute/homes/aharter/isy2020/phyre/flownet.py", line 2763, in load_models
    self.models[model].load_state_dict(T.load(load_path+f'/{model}.pt', map_location=T.device(device)))
  File "/media/compute/homes/aharter/miniconda3/envs/phyre/lib/python3.6/site-packages/torch/serialization.py", line 571, in load
    with _open_file_like(f, 'rb') as opened_file:
  File "/media/compute/homes/aharter/miniconda3/envs/phyre/lib/python3.6/site-packages/torch/serialization.py", line 229, in _open_file_like
    return _open_file(name_or_buffer, mode)
  File "/media/compute/homes/aharter/miniconda3/envs/phyre/lib/python3.6/site-packages/torch/serialization.py", line 210, in __init__
    super(_open_file, self).__init__(open(name, mode))
FileNotFoundError: [Errno 2] No such file or directory: 'saves/flownet/VS-bigbase2_within_0_-1/tar_net.pt'
2020-11-07 04:38:44,336 INFO root Loading cache from /media/compute/homes/aharter/.cache/phyre/offline_simulation/100000/ball
2020-11-07 04:38:52,590 INFO __main__ VS-bigbase2 ball_within_template 0 -1 || loading models...
2020-11-07 04:38:52,595 ERROR __main__ Exception occured:
Traceback (most recent call last):
  File "solver.py", line 231, in <module>
    solver.load_models(setup=eval_setup, fold=fold_id, no_second_stage=no_scnd_stage, load_from=load_from)
  File "/media/compute/homes/aharter/isy2020/phyre/flownet.py", line 2763, in load_models
    self.models[model].load_state_dict(T.load(load_path+f'/{model}.pt', map_location=T.device(device)))
  File "/media/compute/homes/aharter/miniconda3/envs/phyre/lib/python3.6/site-packages/torch/serialization.py", line 571, in load
    with _open_file_like(f, 'rb') as opened_file:
  File "/media/compute/homes/aharter/miniconda3/envs/phyre/lib/python3.6/site-packages/torch/serialization.py", line 229, in _open_file_like
    return _open_file(name_or_buffer, mode)
  File "/media/compute/homes/aharter/miniconda3/envs/phyre/lib/python3.6/site-packages/torch/serialization.py", line 210, in __init__
    super(_open_file, self).__init__(open(name, mode))
FileNotFoundError: [Errno 2] No such file or directory: 'saves/flownet/VS-bigbase2_within_0_-1/tar_net.pt'
2020-11-07 04:45:36,758 INFO root Loading cache from /media/compute/homes/aharter/.cache/phyre/offline_simulation/100000/ball
2020-11-07 04:45:44,915 INFO __main__ VS-bigbase2 ball_within_template 0 -1 || loading models...
2020-11-07 04:45:44,918 ERROR __main__ Exception occured:
Traceback (most recent call last):
  File "solver.py", line 231, in <module>
    solver.load_models(setup=eval_setup, fold=fold_id, no_second_stage=no_scnd_stage, load_from=load_from)
  File "/media/compute/homes/aharter/isy2020/phyre/flownet.py", line 2763, in load_models
    self.models[model].load_state_dict(T.load(load_path+f'/{model}.pt', map_location=T.device(device)))
  File "/media/compute/homes/aharter/miniconda3/envs/phyre/lib/python3.6/site-packages/torch/serialization.py", line 571, in load
    with _open_file_like(f, 'rb') as opened_file:
  File "/media/compute/homes/aharter/miniconda3/envs/phyre/lib/python3.6/site-packages/torch/serialization.py", line 229, in _open_file_like
    return _open_file(name_or_buffer, mode)
  File "/media/compute/homes/aharter/miniconda3/envs/phyre/lib/python3.6/site-packages/torch/serialization.py", line 210, in __init__
    super(_open_file, self).__init__(open(name, mode))
FileNotFoundError: [Errno 2] No such file or directory: 'saves/flownet/VS-bigbase2_within_0_-1/tar_net.pt'
2020-11-07 04:52:26,453 INFO root Loading cache from /media/compute/homes/aharter/.cache/phyre/offline_simulation/100000/ball
2020-11-07 04:52:34,719 INFO __main__ VS-bigbase2 ball_within_template 0 -1 || loading models...
2020-11-07 04:52:34,722 ERROR __main__ Exception occured:
Traceback (most recent call last):
  File "solver.py", line 231, in <module>
    solver.load_models(setup=eval_setup, fold=fold_id, no_second_stage=no_scnd_stage, load_from=load_from)
  File "/media/compute/homes/aharter/isy2020/phyre/flownet.py", line 2763, in load_models
    self.models[model].load_state_dict(T.load(load_path+f'/{model}.pt', map_location=T.device(device)))
  File "/media/compute/homes/aharter/miniconda3/envs/phyre/lib/python3.6/site-packages/torch/serialization.py", line 571, in load
    with _open_file_like(f, 'rb') as opened_file:
  File "/media/compute/homes/aharter/miniconda3/envs/phyre/lib/python3.6/site-packages/torch/serialization.py", line 229, in _open_file_like
    return _open_file(name_or_buffer, mode)
  File "/media/compute/homes/aharter/miniconda3/envs/phyre/lib/python3.6/site-packages/torch/serialization.py", line 210, in __init__
    super(_open_file, self).__init__(open(name, mode))
FileNotFoundError: [Errno 2] No such file or directory: 'saves/flownet/VS-bigbase2_within_0_-1/tar_net.pt'
2020-11-07 08:28:14,127 INFO root Loading cache from /media/compute/homes/aharter/.cache/phyre/offline_simulation/100000/ball
2020-11-07 08:28:22,148 INFO __main__ VS-bigbase2 ball_within_template 0 0.0 || loading models...
2020-11-07 08:28:22,153 ERROR __main__ Exception occured:
Traceback (most recent call last):
  File "solver.py", line 231, in <module>
    solver.load_models(setup=eval_setup, fold=fold_id, no_second_stage=no_scnd_stage, load_from=load_from)
  File "/media/compute/homes/aharter/isy2020/phyre/flownet.py", line 2763, in load_models
    self.models[model].load_state_dict(T.load(load_path+f'/{model}.pt', map_location=T.device(device)))
  File "/media/compute/homes/aharter/miniconda3/envs/phyre/lib/python3.6/site-packages/torch/serialization.py", line 571, in load
    with _open_file_like(f, 'rb') as opened_file:
  File "/media/compute/homes/aharter/miniconda3/envs/phyre/lib/python3.6/site-packages/torch/serialization.py", line 229, in _open_file_like
    return _open_file(name_or_buffer, mode)
  File "/media/compute/homes/aharter/miniconda3/envs/phyre/lib/python3.6/site-packages/torch/serialization.py", line 210, in __init__
    super(_open_file, self).__init__(open(name, mode))
FileNotFoundError: [Errno 2] No such file or directory: 'saves/flownet/VS-bigbase2_within_0_0.0/tar_net.pt'
2020-11-07 08:29:48,206 INFO root Loading cache from /media/compute/homes/aharter/.cache/phyre/offline_simulation/100000/ball
2020-11-07 08:29:56,345 INFO __main__ VS-bigbase2 ball_within_template 0 0 || loading models...
2020-11-07 08:29:57,021 INFO __main__ VS-bigbase2 ball_within_template 0 || getting auccess...
2020-11-07 08:30:09,481 INFO root Loading cache from /media/compute/homes/aharter/.cache/phyre/offline_simulation/100000/ball
2020-11-07 08:49:03,437 INFO root Loading cache from /media/compute/homes/aharter/.cache/phyre/offline_simulation/100000/ball
2020-11-07 08:49:11,668 INFO __main__ VS-bigbase2 ball_cross_template 0 0 || loading models...
2020-11-07 08:49:12,206 INFO __main__ VS-bigbase2 ball_cross_template 0 || getting auccess...
2020-11-07 08:49:24,444 INFO root Loading cache from /media/compute/homes/aharter/.cache/phyre/offline_simulation/100000/ball
2020-11-07 09:06:44,858 INFO __main__ ['ball_within_template', 0.17019821844981475, 'ball_cross_template', 0.20733766384357968]
