2020-11-07 03:52:20,051 INFO root Loading cache from /media/compute/homes/aharter/.cache/phyre/offline_simulation/100000/ball
2020-11-07 03:52:28,157 INFO __main__ VS-bigbase2 ball_within_template 0 -1 || loading models...
2020-11-07 03:52:28,159 ERROR __main__ Exception occured:
Traceback (most recent call last):
  File "solver.py", line 231, in <module>
    solver.load_models(setup=eval_setup, fold=fold_id, no_second_stage=no_scnd_stage, load_from=load_from)
  File "/media/compute/homes/aharter/isy2020/phyre/flownet.py", line 2763, in load_models
    self.models[model].load_state_dict(T.load(load_path+f'/{model}.pt', map_location=T.device(device)))
  File "/media/compute/homes/aharter/miniconda3/envs/phyre/lib/python3.6/site-packages/torch/serialization.py", line 571, in load
    with _open_file_like(f, 'rb') as opened_file:
  File "/media/compute/homes/aharter/miniconda3/envs/phyre/lib/python3.6/site-packages/torch/serialization.py", line 229, in _open_file_like
    return _open_file(name_or_buffer, mode)
  File "/media/compute/homes/aharter/miniconda3/envs/phyre/lib/python3.6/site-packages/torch/serialization.py", line 210, in __init__
    super(_open_file, self).__init__(open(name, mode))
FileNotFoundError: [Errno 2] No such file or directory: 'saves/flownet/VS-bigbase2_within_0_-1/tar_net.pt'
2020-11-07 03:59:08,827 INFO root Loading cache from /media/compute/homes/aharter/.cache/phyre/offline_simulation/100000/ball
2020-11-07 03:59:17,018 INFO __main__ VS-bigbase2 ball_within_template 0 -1 || loading models...
2020-11-07 03:59:17,023 ERROR __main__ Exception occured:
Traceback (most recent call last):
  File "solver.py", line 231, in <module>
    solver.load_models(setup=eval_setup, fold=fold_id, no_second_stage=no_scnd_stage, load_from=load_from)
  File "/media/compute/homes/aharter/isy2020/phyre/flownet.py", line 2763, in load_models
    self.models[model].load_state_dict(T.load(load_path+f'/{model}.pt', map_location=T.device(device)))
  File "/media/compute/homes/aharter/miniconda3/envs/phyre/lib/python3.6/site-packages/torch/serialization.py", line 571, in load
    with _open_file_like(f, 'rb') as opened_file:
  File "/media/compute/homes/aharter/miniconda3/envs/phyre/lib/python3.6/site-packages/torch/serialization.py", line 229, in _open_file_like
    return _open_file(name_or_buffer, mode)
  File "/media/compute/homes/aharter/miniconda3/envs/phyre/lib/python3.6/site-packages/torch/serialization.py", line 210, in __init__
    super(_open_file, self).__init__(open(name, mode))
FileNotFoundError: [Errno 2] No such file or directory: 'saves/flownet/VS-bigbase2_within_0_-1/tar_net.pt'
2020-11-07 04:05:52,436 INFO root Loading cache from /media/compute/homes/aharter/.cache/phyre/offline_simulation/100000/ball
2020-11-07 04:06:00,520 INFO __main__ VS-bigbase2 ball_within_template 0 -1 || loading models...
2020-11-07 04:06:00,523 ERROR __main__ Exception occured:
Traceback (most recent call last):
  File "solver.py", line 231, in <module>
    solver.load_models(setup=eval_setup, fold=fold_id, no_second_stage=no_scnd_stage, load_from=load_from)
  File "/media/compute/homes/aharter/isy2020/phyre/flownet.py", line 2763, in load_models
    self.models[model].load_state_dict(T.load(load_path+f'/{model}.pt', map_location=T.device(device)))
  File "/media/compute/homes/aharter/miniconda3/envs/phyre/lib/python3.6/site-packages/torch/serialization.py", line 571, in load
    with _open_file_like(f, 'rb') as opened_file:
  File "/media/compute/homes/aharter/miniconda3/envs/phyre/lib/python3.6/site-packages/torch/serialization.py", line 229, in _open_file_like
    return _open_file(name_or_buffer, mode)
  File "/media/compute/homes/aharter/miniconda3/envs/phyre/lib/python3.6/site-packages/torch/serialization.py", line 210, in __init__
    super(_open_file, self).__init__(open(name, mode))
FileNotFoundError: [Errno 2] No such file or directory: 'saves/flownet/VS-bigbase2_within_0_-1/tar_net.pt'
2020-11-07 04:12:43,689 INFO root Loading cache from /media/compute/homes/aharter/.cache/phyre/offline_simulation/100000/ball
2020-11-07 04:12:51,780 INFO __main__ VS-bigbase2 ball_within_template 0 -1 || loading models...
2020-11-07 04:12:51,783 ERROR __main__ Exception occured:
Traceback (most recent call last):
  File "solver.py", line 231, in <module>
    solver.load_models(setup=eval_setup, fold=fold_id, no_second_stage=no_scnd_stage, load_from=load_from)
  File "/media/compute/homes/aharter/isy2020/phyre/flownet.py", line 2763, in load_models
    self.models[model].load_state_dict(T.load(load_path+f'/{model}.pt', map_location=T.device(device)))
  File "/media/compute/homes/aharter/miniconda3/envs/phyre/lib/python3.6/site-packages/torch/serialization.py", line 571, in load
    with _open_file_like(f, 'rb') as opened_file:
  File "/media/compute/homes/aharter/miniconda3/envs/phyre/lib/python3.6/site-packages/torch/serialization.py", line 229, in _open_file_like
    return _open_file(name_or_buffer, mode)
  File "/media/compute/homes/aharter/miniconda3/envs/phyre/lib/python3.6/site-packages/torch/serialization.py", line 210, in __init__
    super(_open_file, self).__init__(open(name, mode))
FileNotFoundError: [Errno 2] No such file or directory: 'saves/flownet/VS-bigbase2_within_0_-1/tar_net.pt'
2020-11-07 04:19:33,530 INFO root Loading cache from /media/compute/homes/aharter/.cache/phyre/offline_simulation/100000/ball
2020-11-07 04:19:41,485 INFO __main__ VS-bigbase2 ball_within_template 0 -1 || loading models...
2020-11-07 04:19:41,489 ERROR __main__ Exception occured:
Traceback (most recent call last):
  File "solver.py", line 231, in <module>
    solver.load_models(setup=eval_setup, fold=fold_id, no_second_stage=no_scnd_stage, load_from=load_from)
  File "/media/compute/homes/aharter/isy2020/phyre/flownet.py", line 2763, in load_models
    self.models[model].load_state_dict(T.load(load_path+f'/{model}.pt', map_location=T.device(device)))
  File "/media/compute/homes/aharter/miniconda3/envs/phyre/lib/python3.6/site-packages/torch/serialization.py", line 571, in load
    with _open_file_like(f, 'rb') as opened_file:
  File "/media/compute/homes/aharter/miniconda3/envs/phyre/lib/python3.6/site-packages/torch/serialization.py", line 229, in _open_file_like
    return _open_file(name_or_buffer, mode)
  File "/media/compute/homes/aharter/miniconda3/envs/phyre/lib/python3.6/site-packages/torch/serialization.py", line 210, in __init__
    super(_open_file, self).__init__(open(name, mode))
FileNotFoundError: [Errno 2] No such file or directory: 'saves/flownet/VS-bigbase2_within_0_-1/tar_net.pt'
2020-11-07 04:26:25,215 INFO root Loading cache from /media/compute/homes/aharter/.cache/phyre/offline_simulation/100000/ball
2020-11-07 04:26:33,349 INFO __main__ VS-bigbase2 ball_within_template 0 -1 || loading models...
2020-11-07 04:26:33,351 ERROR __main__ Exception occured:
Traceback (most recent call last):
  File "solver.py", line 231, in <module>
    solver.load_models(setup=eval_setup, fold=fold_id, no_second_stage=no_scnd_stage, load_from=load_from)
  File "/media/compute/homes/aharter/isy2020/phyre/flownet.py", line 2763, in load_models
    self.models[model].load_state_dict(T.load(load_path+f'/{model}.pt', map_location=T.device(device)))
  File "/media/compute/homes/aharter/miniconda3/envs/phyre/lib/python3.6/site-packages/torch/serialization.py", line 571, in load
    with _open_file_like(f, 'rb') as opened_file:
  File "/media/compute/homes/aharter/miniconda3/envs/phyre/lib/python3.6/site-packages/torch/serialization.py", line 229, in _open_file_like
    return _open_file(name_or_buffer, mode)
  File "/media/compute/homes/aharter/miniconda3/envs/phyre/lib/python3.6/site-packages/torch/serialization.py", line 210, in __init__
    super(_open_file, self).__init__(open(name, mode))
FileNotFoundError: [Errno 2] No such file or directory: 'saves/flownet/VS-bigbase2_within_0_-1/tar_net.pt'
2020-11-07 04:33:16,957 INFO root Loading cache from /media/compute/homes/aharter/.cache/phyre/offline_simulation/100000/ball
2020-11-07 04:33:25,160 INFO __main__ VS-bigbase2 ball_within_template 0 -1 || loading models...
2020-11-07 04:33:25,162 ERROR __main__ Exception occured:
Traceback (most recent call last):
  File "solver.py", line 231, in <module>
    solver.load_models(setup=eval_setup, fold=fold_id, no_second_stage=no_scnd_stage, load_from=load_from)
  File "/media/compute/homes/aharter/isy2020/phyre/flownet.py", line 2763, in load_models
    self.models[model].load_state_dict(T.load(load_path+f'/{model}.pt', map_location=T.device(device)))
  File "/media/compute/homes/aharter/miniconda3/envs/phyre/lib/python3.6/site-packages/torch/serialization.py", line 571, in load
    with _open_file_like(f, 'rb') as opened_file:
  File "/media/compute/homes/aharter/miniconda3/envs/phyre/lib/python3.6/site-packages/torch/serialization.py", line 229, in _open_file_like
    return _open_file(name_or_buffer, mode)
  File "/media/compute/homes/aharter/miniconda3/envs/phyre/lib/python3.6/site-packages/torch/serialization.py", line 210, in __init__
    super(_open_file, self).__init__(open(name, mode))
FileNotFoundError: [Errno 2] No such file or directory: 'saves/flownet/VS-bigbase2_within_0_-1/tar_net.pt'
2020-11-07 04:40:06,020 INFO root Loading cache from /media/compute/homes/aharter/.cache/phyre/offline_simulation/100000/ball
2020-11-07 04:40:14,167 INFO __main__ VS-bigbase2 ball_within_template 0 -1 || loading models...
2020-11-07 04:40:14,170 ERROR __main__ Exception occured:
Traceback (most recent call last):
  File "solver.py", line 231, in <module>
    solver.load_models(setup=eval_setup, fold=fold_id, no_second_stage=no_scnd_stage, load_from=load_from)
  File "/media/compute/homes/aharter/isy2020/phyre/flownet.py", line 2763, in load_models
    self.models[model].load_state_dict(T.load(load_path+f'/{model}.pt', map_location=T.device(device)))
  File "/media/compute/homes/aharter/miniconda3/envs/phyre/lib/python3.6/site-packages/torch/serialization.py", line 571, in load
    with _open_file_like(f, 'rb') as opened_file:
  File "/media/compute/homes/aharter/miniconda3/envs/phyre/lib/python3.6/site-packages/torch/serialization.py", line 229, in _open_file_like
    return _open_file(name_or_buffer, mode)
  File "/media/compute/homes/aharter/miniconda3/envs/phyre/lib/python3.6/site-packages/torch/serialization.py", line 210, in __init__
    super(_open_file, self).__init__(open(name, mode))
FileNotFoundError: [Errno 2] No such file or directory: 'saves/flownet/VS-bigbase2_within_0_-1/tar_net.pt'
2020-11-07 04:46:58,919 INFO root Loading cache from /media/compute/homes/aharter/.cache/phyre/offline_simulation/100000/ball
2020-11-07 04:47:06,819 INFO __main__ VS-bigbase2 ball_within_template 0 -1 || loading models...
2020-11-07 04:47:06,821 ERROR __main__ Exception occured:
Traceback (most recent call last):
  File "solver.py", line 231, in <module>
    solver.load_models(setup=eval_setup, fold=fold_id, no_second_stage=no_scnd_stage, load_from=load_from)
  File "/media/compute/homes/aharter/isy2020/phyre/flownet.py", line 2763, in load_models
    self.models[model].load_state_dict(T.load(load_path+f'/{model}.pt', map_location=T.device(device)))
  File "/media/compute/homes/aharter/miniconda3/envs/phyre/lib/python3.6/site-packages/torch/serialization.py", line 571, in load
    with _open_file_like(f, 'rb') as opened_file:
  File "/media/compute/homes/aharter/miniconda3/envs/phyre/lib/python3.6/site-packages/torch/serialization.py", line 229, in _open_file_like
    return _open_file(name_or_buffer, mode)
  File "/media/compute/homes/aharter/miniconda3/envs/phyre/lib/python3.6/site-packages/torch/serialization.py", line 210, in __init__
    super(_open_file, self).__init__(open(name, mode))
FileNotFoundError: [Errno 2] No such file or directory: 'saves/flownet/VS-bigbase2_within_0_-1/tar_net.pt'
2020-11-07 04:53:48,649 INFO root Loading cache from /media/compute/homes/aharter/.cache/phyre/offline_simulation/100000/ball
2020-11-07 04:53:56,797 INFO __main__ VS-bigbase2 ball_within_template 0 -1 || loading models...
2020-11-07 04:53:56,799 ERROR __main__ Exception occured:
Traceback (most recent call last):
  File "solver.py", line 231, in <module>
    solver.load_models(setup=eval_setup, fold=fold_id, no_second_stage=no_scnd_stage, load_from=load_from)
  File "/media/compute/homes/aharter/isy2020/phyre/flownet.py", line 2763, in load_models
    self.models[model].load_state_dict(T.load(load_path+f'/{model}.pt', map_location=T.device(device)))
  File "/media/compute/homes/aharter/miniconda3/envs/phyre/lib/python3.6/site-packages/torch/serialization.py", line 571, in load
    with _open_file_like(f, 'rb') as opened_file:
  File "/media/compute/homes/aharter/miniconda3/envs/phyre/lib/python3.6/site-packages/torch/serialization.py", line 229, in _open_file_like
    return _open_file(name_or_buffer, mode)
  File "/media/compute/homes/aharter/miniconda3/envs/phyre/lib/python3.6/site-packages/torch/serialization.py", line 210, in __init__
    super(_open_file, self).__init__(open(name, mode))
FileNotFoundError: [Errno 2] No such file or directory: 'saves/flownet/VS-bigbase2_within_0_-1/tar_net.pt'
2020-11-07 12:03:45,622 INFO root Loading cache from /media/compute/homes/aharter/.cache/phyre/offline_simulation/100000/ball
2020-11-07 12:03:52,888 INFO __main__ VS-bigbase2 ball_within_template 0 2 || loading models...
2020-11-07 12:03:53,510 INFO __main__ VS-bigbase2 ball_within_template 0 || getting auccess...
2020-11-07 12:04:03,978 INFO root Loading cache from /media/compute/homes/aharter/.cache/phyre/offline_simulation/100000/ball
2020-11-07 12:18:43,189 INFO root Loading cache from /media/compute/homes/aharter/.cache/phyre/offline_simulation/100000/ball
2020-11-07 12:18:49,908 INFO __main__ VS-bigbase2 ball_cross_template 0 2 || loading models...
2020-11-07 12:18:50,286 INFO __main__ VS-bigbase2 ball_cross_template 0 || getting auccess...
2020-11-07 12:18:59,175 INFO root Loading cache from /media/compute/homes/aharter/.cache/phyre/offline_simulation/100000/ball
2020-11-07 12:34:56,908 INFO __main__ ['ball_within_template', 0.30664973497650094, 'ball_cross_template', 0.2504930874333501]
