2020-11-07 03:51:38,444 INFO root Loading cache from /media/compute/homes/aharter/.cache/phyre/offline_simulation/100000/ball
2020-11-07 03:51:46,755 INFO __main__ VS-bigbase2 ball_within_template 0 -1 || loading models...
2020-11-07 03:51:46,757 ERROR __main__ Exception occured:
Traceback (most recent call last):
  File "solver.py", line 231, in <module>
    solver.load_models(setup=eval_setup, fold=fold_id, no_second_stage=no_scnd_stage, load_from=load_from)
  File "/media/compute/homes/aharter/isy2020/phyre/flownet.py", line 2763, in load_models
    self.models[model].load_state_dict(T.load(load_path+f'/{model}.pt', map_location=T.device(device)))
  File "/media/compute/homes/aharter/miniconda3/envs/phyre/lib/python3.6/site-packages/torch/serialization.py", line 571, in load
    with _open_file_like(f, 'rb') as opened_file:
  File "/media/compute/homes/aharter/miniconda3/envs/phyre/lib/python3.6/site-packages/torch/serialization.py", line 229, in _open_file_like
    return _open_file(name_or_buffer, mode)
  File "/media/compute/homes/aharter/miniconda3/envs/phyre/lib/python3.6/site-packages/torch/serialization.py", line 210, in __init__
    super(_open_file, self).__init__(open(name, mode))
FileNotFoundError: [Errno 2] No such file or directory: 'saves/flownet/VS-bigbase2_within_0_-1/tar_net.pt'
2020-11-07 03:58:28,024 INFO root Loading cache from /media/compute/homes/aharter/.cache/phyre/offline_simulation/100000/ball
2020-11-07 03:58:36,137 INFO __main__ VS-bigbase2 ball_within_template 0 -1 || loading models...
2020-11-07 03:58:36,140 ERROR __main__ Exception occured:
Traceback (most recent call last):
  File "solver.py", line 231, in <module>
    solver.load_models(setup=eval_setup, fold=fold_id, no_second_stage=no_scnd_stage, load_from=load_from)
  File "/media/compute/homes/aharter/isy2020/phyre/flownet.py", line 2763, in load_models
    self.models[model].load_state_dict(T.load(load_path+f'/{model}.pt', map_location=T.device(device)))
  File "/media/compute/homes/aharter/miniconda3/envs/phyre/lib/python3.6/site-packages/torch/serialization.py", line 571, in load
    with _open_file_like(f, 'rb') as opened_file:
  File "/media/compute/homes/aharter/miniconda3/envs/phyre/lib/python3.6/site-packages/torch/serialization.py", line 229, in _open_file_like
    return _open_file(name_or_buffer, mode)
  File "/media/compute/homes/aharter/miniconda3/envs/phyre/lib/python3.6/site-packages/torch/serialization.py", line 210, in __init__
    super(_open_file, self).__init__(open(name, mode))
FileNotFoundError: [Errno 2] No such file or directory: 'saves/flownet/VS-bigbase2_within_0_-1/tar_net.pt'
2020-11-07 04:05:11,222 INFO root Loading cache from /media/compute/homes/aharter/.cache/phyre/offline_simulation/100000/ball
2020-11-07 04:05:19,210 INFO __main__ VS-bigbase2 ball_within_template 0 -1 || loading models...
2020-11-07 04:05:19,212 ERROR __main__ Exception occured:
Traceback (most recent call last):
  File "solver.py", line 231, in <module>
    solver.load_models(setup=eval_setup, fold=fold_id, no_second_stage=no_scnd_stage, load_from=load_from)
  File "/media/compute/homes/aharter/isy2020/phyre/flownet.py", line 2763, in load_models
    self.models[model].load_state_dict(T.load(load_path+f'/{model}.pt', map_location=T.device(device)))
  File "/media/compute/homes/aharter/miniconda3/envs/phyre/lib/python3.6/site-packages/torch/serialization.py", line 571, in load
    with _open_file_like(f, 'rb') as opened_file:
  File "/media/compute/homes/aharter/miniconda3/envs/phyre/lib/python3.6/site-packages/torch/serialization.py", line 229, in _open_file_like
    return _open_file(name_or_buffer, mode)
  File "/media/compute/homes/aharter/miniconda3/envs/phyre/lib/python3.6/site-packages/torch/serialization.py", line 210, in __init__
    super(_open_file, self).__init__(open(name, mode))
FileNotFoundError: [Errno 2] No such file or directory: 'saves/flownet/VS-bigbase2_within_0_-1/tar_net.pt'
2020-11-07 04:12:01,826 INFO root Loading cache from /media/compute/homes/aharter/.cache/phyre/offline_simulation/100000/ball
2020-11-07 04:12:09,952 INFO __main__ VS-bigbase2 ball_within_template 0 -1 || loading models...
2020-11-07 04:12:09,955 ERROR __main__ Exception occured:
Traceback (most recent call last):
  File "solver.py", line 231, in <module>
    solver.load_models(setup=eval_setup, fold=fold_id, no_second_stage=no_scnd_stage, load_from=load_from)
  File "/media/compute/homes/aharter/isy2020/phyre/flownet.py", line 2763, in load_models
    self.models[model].load_state_dict(T.load(load_path+f'/{model}.pt', map_location=T.device(device)))
  File "/media/compute/homes/aharter/miniconda3/envs/phyre/lib/python3.6/site-packages/torch/serialization.py", line 571, in load
    with _open_file_like(f, 'rb') as opened_file:
  File "/media/compute/homes/aharter/miniconda3/envs/phyre/lib/python3.6/site-packages/torch/serialization.py", line 229, in _open_file_like
    return _open_file(name_or_buffer, mode)
  File "/media/compute/homes/aharter/miniconda3/envs/phyre/lib/python3.6/site-packages/torch/serialization.py", line 210, in __init__
    super(_open_file, self).__init__(open(name, mode))
FileNotFoundError: [Errno 2] No such file or directory: 'saves/flownet/VS-bigbase2_within_0_-1/tar_net.pt'
2020-11-07 04:18:52,092 INFO root Loading cache from /media/compute/homes/aharter/.cache/phyre/offline_simulation/100000/ball
2020-11-07 04:19:00,116 INFO __main__ VS-bigbase2 ball_within_template 0 -1 || loading models...
2020-11-07 04:19:00,118 ERROR __main__ Exception occured:
Traceback (most recent call last):
  File "solver.py", line 231, in <module>
    solver.load_models(setup=eval_setup, fold=fold_id, no_second_stage=no_scnd_stage, load_from=load_from)
  File "/media/compute/homes/aharter/isy2020/phyre/flownet.py", line 2763, in load_models
    self.models[model].load_state_dict(T.load(load_path+f'/{model}.pt', map_location=T.device(device)))
  File "/media/compute/homes/aharter/miniconda3/envs/phyre/lib/python3.6/site-packages/torch/serialization.py", line 571, in load
    with _open_file_like(f, 'rb') as opened_file:
  File "/media/compute/homes/aharter/miniconda3/envs/phyre/lib/python3.6/site-packages/torch/serialization.py", line 229, in _open_file_like
    return _open_file(name_or_buffer, mode)
  File "/media/compute/homes/aharter/miniconda3/envs/phyre/lib/python3.6/site-packages/torch/serialization.py", line 210, in __init__
    super(_open_file, self).__init__(open(name, mode))
FileNotFoundError: [Errno 2] No such file or directory: 'saves/flownet/VS-bigbase2_within_0_-1/tar_net.pt'
2020-11-07 04:25:44,307 INFO root Loading cache from /media/compute/homes/aharter/.cache/phyre/offline_simulation/100000/ball
2020-11-07 04:25:52,264 INFO __main__ VS-bigbase2 ball_within_template 0 -1 || loading models...
2020-11-07 04:25:52,266 ERROR __main__ Exception occured:
Traceback (most recent call last):
  File "solver.py", line 231, in <module>
    solver.load_models(setup=eval_setup, fold=fold_id, no_second_stage=no_scnd_stage, load_from=load_from)
  File "/media/compute/homes/aharter/isy2020/phyre/flownet.py", line 2763, in load_models
    self.models[model].load_state_dict(T.load(load_path+f'/{model}.pt', map_location=T.device(device)))
  File "/media/compute/homes/aharter/miniconda3/envs/phyre/lib/python3.6/site-packages/torch/serialization.py", line 571, in load
    with _open_file_like(f, 'rb') as opened_file:
  File "/media/compute/homes/aharter/miniconda3/envs/phyre/lib/python3.6/site-packages/torch/serialization.py", line 229, in _open_file_like
    return _open_file(name_or_buffer, mode)
  File "/media/compute/homes/aharter/miniconda3/envs/phyre/lib/python3.6/site-packages/torch/serialization.py", line 210, in __init__
    super(_open_file, self).__init__(open(name, mode))
FileNotFoundError: [Errno 2] No such file or directory: 'saves/flownet/VS-bigbase2_within_0_-1/tar_net.pt'
2020-11-07 04:32:35,175 INFO root Loading cache from /media/compute/homes/aharter/.cache/phyre/offline_simulation/100000/ball
2020-11-07 04:32:43,283 INFO __main__ VS-bigbase2 ball_within_template 0 -1 || loading models...
2020-11-07 04:32:43,286 ERROR __main__ Exception occured:
Traceback (most recent call last):
  File "solver.py", line 231, in <module>
    solver.load_models(setup=eval_setup, fold=fold_id, no_second_stage=no_scnd_stage, load_from=load_from)
  File "/media/compute/homes/aharter/isy2020/phyre/flownet.py", line 2763, in load_models
    self.models[model].load_state_dict(T.load(load_path+f'/{model}.pt', map_location=T.device(device)))
  File "/media/compute/homes/aharter/miniconda3/envs/phyre/lib/python3.6/site-packages/torch/serialization.py", line 571, in load
    with _open_file_like(f, 'rb') as opened_file:
  File "/media/compute/homes/aharter/miniconda3/envs/phyre/lib/python3.6/site-packages/torch/serialization.py", line 229, in _open_file_like
    return _open_file(name_or_buffer, mode)
  File "/media/compute/homes/aharter/miniconda3/envs/phyre/lib/python3.6/site-packages/torch/serialization.py", line 210, in __init__
    super(_open_file, self).__init__(open(name, mode))
FileNotFoundError: [Errno 2] No such file or directory: 'saves/flownet/VS-bigbase2_within_0_-1/tar_net.pt'
2020-11-07 04:39:25,089 INFO root Loading cache from /media/compute/homes/aharter/.cache/phyre/offline_simulation/100000/ball
2020-11-07 04:39:33,179 INFO __main__ VS-bigbase2 ball_within_template 0 -1 || loading models...
2020-11-07 04:39:33,182 ERROR __main__ Exception occured:
Traceback (most recent call last):
  File "solver.py", line 231, in <module>
    solver.load_models(setup=eval_setup, fold=fold_id, no_second_stage=no_scnd_stage, load_from=load_from)
  File "/media/compute/homes/aharter/isy2020/phyre/flownet.py", line 2763, in load_models
    self.models[model].load_state_dict(T.load(load_path+f'/{model}.pt', map_location=T.device(device)))
  File "/media/compute/homes/aharter/miniconda3/envs/phyre/lib/python3.6/site-packages/torch/serialization.py", line 571, in load
    with _open_file_like(f, 'rb') as opened_file:
  File "/media/compute/homes/aharter/miniconda3/envs/phyre/lib/python3.6/site-packages/torch/serialization.py", line 229, in _open_file_like
    return _open_file(name_or_buffer, mode)
  File "/media/compute/homes/aharter/miniconda3/envs/phyre/lib/python3.6/site-packages/torch/serialization.py", line 210, in __init__
    super(_open_file, self).__init__(open(name, mode))
FileNotFoundError: [Errno 2] No such file or directory: 'saves/flownet/VS-bigbase2_within_0_-1/tar_net.pt'
2020-11-07 04:46:17,289 INFO root Loading cache from /media/compute/homes/aharter/.cache/phyre/offline_simulation/100000/ball
2020-11-07 04:46:25,316 INFO __main__ VS-bigbase2 ball_within_template 0 -1 || loading models...
2020-11-07 04:46:25,319 ERROR __main__ Exception occured:
Traceback (most recent call last):
  File "solver.py", line 231, in <module>
    solver.load_models(setup=eval_setup, fold=fold_id, no_second_stage=no_scnd_stage, load_from=load_from)
  File "/media/compute/homes/aharter/isy2020/phyre/flownet.py", line 2763, in load_models
    self.models[model].load_state_dict(T.load(load_path+f'/{model}.pt', map_location=T.device(device)))
  File "/media/compute/homes/aharter/miniconda3/envs/phyre/lib/python3.6/site-packages/torch/serialization.py", line 571, in load
    with _open_file_like(f, 'rb') as opened_file:
  File "/media/compute/homes/aharter/miniconda3/envs/phyre/lib/python3.6/site-packages/torch/serialization.py", line 229, in _open_file_like
    return _open_file(name_or_buffer, mode)
  File "/media/compute/homes/aharter/miniconda3/envs/phyre/lib/python3.6/site-packages/torch/serialization.py", line 210, in __init__
    super(_open_file, self).__init__(open(name, mode))
FileNotFoundError: [Errno 2] No such file or directory: 'saves/flownet/VS-bigbase2_within_0_-1/tar_net.pt'
2020-11-07 04:53:07,188 INFO root Loading cache from /media/compute/homes/aharter/.cache/phyre/offline_simulation/100000/ball
2020-11-07 04:53:15,261 INFO __main__ VS-bigbase2 ball_within_template 0 -1 || loading models...
2020-11-07 04:53:15,265 ERROR __main__ Exception occured:
Traceback (most recent call last):
  File "solver.py", line 231, in <module>
    solver.load_models(setup=eval_setup, fold=fold_id, no_second_stage=no_scnd_stage, load_from=load_from)
  File "/media/compute/homes/aharter/isy2020/phyre/flownet.py", line 2763, in load_models
    self.models[model].load_state_dict(T.load(load_path+f'/{model}.pt', map_location=T.device(device)))
  File "/media/compute/homes/aharter/miniconda3/envs/phyre/lib/python3.6/site-packages/torch/serialization.py", line 571, in load
    with _open_file_like(f, 'rb') as opened_file:
  File "/media/compute/homes/aharter/miniconda3/envs/phyre/lib/python3.6/site-packages/torch/serialization.py", line 229, in _open_file_like
    return _open_file(name_or_buffer, mode)
  File "/media/compute/homes/aharter/miniconda3/envs/phyre/lib/python3.6/site-packages/torch/serialization.py", line 210, in __init__
    super(_open_file, self).__init__(open(name, mode))
FileNotFoundError: [Errno 2] No such file or directory: 'saves/flownet/VS-bigbase2_within_0_-1/tar_net.pt'
2020-11-07 08:28:54,217 INFO root Loading cache from /media/compute/homes/aharter/.cache/phyre/offline_simulation/100000/ball
2020-11-07 10:24:06,268 INFO root Loading cache from /media/compute/homes/aharter/.cache/phyre/offline_simulation/100000/ball
2020-11-07 10:24:13,265 INFO __main__ VS-bigbase2 ball_within_template 0 1 || loading models...
2020-11-07 10:24:13,901 INFO __main__ VS-bigbase2 ball_within_template 0 || getting auccess...
2020-11-07 10:24:25,038 INFO root Loading cache from /media/compute/homes/aharter/.cache/phyre/offline_simulation/100000/ball
2020-11-07 10:40:25,572 INFO root Loading cache from /media/compute/homes/aharter/.cache/phyre/offline_simulation/100000/ball
2020-11-07 10:40:32,127 INFO __main__ VS-bigbase2 ball_cross_template 0 1 || loading models...
2020-11-07 10:40:32,574 INFO __main__ VS-bigbase2 ball_cross_template 0 || getting auccess...
2020-11-07 10:40:42,353 INFO root Loading cache from /media/compute/homes/aharter/.cache/phyre/offline_simulation/100000/ball
2020-11-07 10:56:21,311 INFO __main__ ['ball_within_template', 0.2720824369206959, 'ball_cross_template', 0.26410199582610877]
